[2024-07-14T06:21:11.096+0000] {local_task_job_runner.py:120} INFO - ::group::Pre task execution logs
[2024-07-14T06:21:11.121+0000] {taskinstance.py:2076} INFO - Dependencies all met for dep_context=non-requeueable deps ti=<TaskInstance: kubernetes_operator_example.kubernetes_task scheduled__2024-07-12T00:00:00+00:00 [queued]>
[2024-07-14T06:21:11.134+0000] {taskinstance.py:2076} INFO - Dependencies all met for dep_context=requeueable deps ti=<TaskInstance: kubernetes_operator_example.kubernetes_task scheduled__2024-07-12T00:00:00+00:00 [queued]>
[2024-07-14T06:21:11.134+0000] {taskinstance.py:2306} INFO - Starting attempt 1 of 2
[2024-07-14T06:21:11.159+0000] {taskinstance.py:2330} INFO - Executing <Task(KubernetesPodOperator): kubernetes_task> on 2024-07-12 00:00:00+00:00
[2024-07-14T06:21:11.168+0000] {warnings.py:112} WARNING - /home/***/.local/lib/python3.12/site-packages/***/task/task_runner/standard_task_runner.py:61: DeprecationWarning: This process (pid=63) is multi-threaded, use of fork() may lead to deadlocks in the child.
  pid = os.fork()

[2024-07-14T06:21:11.170+0000] {standard_task_runner.py:63} INFO - Started process 68 to run task
[2024-07-14T06:21:11.169+0000] {standard_task_runner.py:90} INFO - Running: ['***', 'tasks', 'run', 'kubernetes_operator_example', 'kubernetes_task', 'scheduled__2024-07-12T00:00:00+00:00', '--job-id', '316', '--raw', '--subdir', 'DAGS_FOLDER/my_dag.py', '--cfg-path', '/tmp/tmp8ufgumrt']
[2024-07-14T06:21:11.172+0000] {standard_task_runner.py:91} INFO - Job 316: Subtask kubernetes_task
[2024-07-14T06:21:11.226+0000] {task_command.py:426} INFO - Running <TaskInstance: kubernetes_operator_example.kubernetes_task scheduled__2024-07-12T00:00:00+00:00 [running]> on host 3d1f449535f3
[2024-07-14T06:21:11.344+0000] {taskinstance.py:2648} INFO - Exporting env vars: AIRFLOW_CTX_DAG_OWNER='***' AIRFLOW_CTX_DAG_ID='kubernetes_operator_example' AIRFLOW_CTX_TASK_ID='kubernetes_task' AIRFLOW_CTX_EXECUTION_DATE='2024-07-12T00:00:00+00:00' AIRFLOW_CTX_TRY_NUMBER='1' AIRFLOW_CTX_DAG_RUN_ID='scheduled__2024-07-12T00:00:00+00:00'
[2024-07-14T06:21:11.347+0000] {taskinstance.py:430} INFO - ::endgroup::
[2024-07-14T06:21:11.355+0000] {pod.py:1121} INFO - Building pod kubernetes-task-togi5o59 with labels: {'dag_id': 'kubernetes_operator_example', 'task_id': 'kubernetes_task', 'run_id': 'scheduled__2024-07-12T0000000000-8be808366', 'kubernetes_pod_operator': 'True', 'try_number': '1'}
[2024-07-14T06:21:11.367+0000] {taskinstance.py:441} INFO - ::group::Post task execution logs
[2024-07-14T06:21:11.367+0000] {taskinstance.py:2905} ERROR - Task failed with exception
Traceback (most recent call last):
  File "/home/airflow/.local/lib/python3.12/site-packages/airflow/providers/cncf/kubernetes/hooks/kubernetes.py", line 267, in _get_default_client
    config.load_incluster_config(client_configuration=self.client_configuration)
  File "/home/airflow/.local/lib/python3.12/site-packages/kubernetes/config/incluster_config.py", line 121, in load_incluster_config
    try_refresh_token=try_refresh_token).load_and_set(client_configuration)
                                         ^^^^^^^^^^^^^^^^^^^^^^^^^^^^^^^^^^
  File "/home/airflow/.local/lib/python3.12/site-packages/kubernetes/config/incluster_config.py", line 54, in load_and_set
    self._load_config()
  File "/home/airflow/.local/lib/python3.12/site-packages/kubernetes/config/incluster_config.py", line 62, in _load_config
    raise ConfigException("Service host/port is not set.")
kubernetes.config.config_exception.ConfigException: Service host/port is not set.

During handling of the above exception, another exception occurred:

Traceback (most recent call last):
  File "/home/airflow/.local/lib/python3.12/site-packages/airflow/models/taskinstance.py", line 465, in _execute_task
    result = _execute_callable(context=context, **execute_callable_kwargs)
             ^^^^^^^^^^^^^^^^^^^^^^^^^^^^^^^^^^^^^^^^^^^^^^^^^^^^^^^^^^^^^
  File "/home/airflow/.local/lib/python3.12/site-packages/airflow/models/taskinstance.py", line 432, in _execute_callable
    return execute_callable(context=context, **execute_callable_kwargs)
           ^^^^^^^^^^^^^^^^^^^^^^^^^^^^^^^^^^^^^^^^^^^^^^^^^^^^^^^^^^^^
  File "/home/airflow/.local/lib/python3.12/site-packages/airflow/models/baseoperator.py", line 401, in wrapper
    return func(self, *args, **kwargs)
           ^^^^^^^^^^^^^^^^^^^^^^^^^^^
  File "/home/airflow/.local/lib/python3.12/site-packages/airflow/providers/cncf/kubernetes/operators/pod.py", line 591, in execute
    return self.execute_sync(context)
           ^^^^^^^^^^^^^^^^^^^^^^^^^^
  File "/home/airflow/.local/lib/python3.12/site-packages/airflow/providers/cncf/kubernetes/operators/pod.py", line 599, in execute_sync
    self.pod_request_obj = self.build_pod_request_obj(context)
                           ^^^^^^^^^^^^^^^^^^^^^^^^^^^^^^^^^^^
  File "/home/airflow/.local/lib/python3.12/site-packages/airflow/providers/cncf/kubernetes/operators/pod.py", line 1130, in build_pod_request_obj
    "airflow_kpo_in_cluster": str(self.hook.is_in_cluster),
                                  ^^^^^^^^^^^^^^^^^^^^^^^
  File "/home/airflow/.local/lib/python3.12/site-packages/airflow/providers/cncf/kubernetes/hooks/kubernetes.py", line 283, in is_in_cluster
    self.api_client  # so we can determine if we are in_cluster or not
    ^^^^^^^^^^^^^^^
  File "/usr/local/lib/python3.12/functools.py", line 995, in __get__
    val = self.func(instance)
          ^^^^^^^^^^^^^^^^^^^
  File "/home/airflow/.local/lib/python3.12/site-packages/airflow/providers/cncf/kubernetes/hooks/kubernetes.py", line 291, in api_client
    return self.get_conn()
           ^^^^^^^^^^^^^^^
  File "/home/airflow/.local/lib/python3.12/site-packages/airflow/providers/cncf/kubernetes/hooks/kubernetes.py", line 259, in get_conn
    return self._get_default_client(cluster_context=cluster_context)
           ^^^^^^^^^^^^^^^^^^^^^^^^^^^^^^^^^^^^^^^^^^^^^^^^^^^^^^^^^
  File "/home/airflow/.local/lib/python3.12/site-packages/airflow/providers/cncf/kubernetes/hooks/kubernetes.py", line 272, in _get_default_client
    config.load_kube_config(
  File "/home/airflow/.local/lib/python3.12/site-packages/kubernetes/config/kube_config.py", line 815, in load_kube_config
    loader = _get_kube_config_loader(
             ^^^^^^^^^^^^^^^^^^^^^^^^
  File "/home/airflow/.local/lib/python3.12/site-packages/kubernetes/config/kube_config.py", line 772, in _get_kube_config_loader
    raise ConfigException(
kubernetes.config.config_exception.ConfigException: Invalid kube-config file. No configuration found.
[2024-07-14T06:21:11.381+0000] {taskinstance.py:1206} INFO - Marking task as UP_FOR_RETRY. dag_id=kubernetes_operator_example, task_id=kubernetes_task, run_id=scheduled__2024-07-12T00:00:00+00:00, execution_date=20240712T000000, start_date=20240714T062111, end_date=20240714T062111
[2024-07-14T06:21:11.394+0000] {standard_task_runner.py:110} ERROR - Failed to execute job 316 for task kubernetes_task (Invalid kube-config file. No configuration found.; 68)
[2024-07-14T06:21:11.424+0000] {local_task_job_runner.py:240} INFO - Task exited with return code 1
[2024-07-14T06:21:11.448+0000] {taskinstance.py:3503} INFO - 0 downstream tasks scheduled from follow-on schedule check
[2024-07-14T06:21:11.450+0000] {local_task_job_runner.py:222} INFO - ::endgroup::
