[2024-07-16T02:56:06.574+0000] {local_task_job_runner.py:120} INFO - ::group::Pre task execution logs
[2024-07-16T02:56:06.595+0000] {taskinstance.py:2076} INFO - Dependencies all met for dep_context=non-requeueable deps ti=<TaskInstance: kubernetes_operator_example.kubernetes_task scheduled__2024-07-15T00:00:00+00:00 [queued]>
[2024-07-16T02:56:06.604+0000] {taskinstance.py:2076} INFO - Dependencies all met for dep_context=requeueable deps ti=<TaskInstance: kubernetes_operator_example.kubernetes_task scheduled__2024-07-15T00:00:00+00:00 [queued]>
[2024-07-16T02:56:06.604+0000] {taskinstance.py:2306} INFO - Starting attempt 2 of 2
[2024-07-16T02:56:06.622+0000] {taskinstance.py:2330} INFO - Executing <Task(KubernetesPodOperator): kubernetes_task> on 2024-07-15 00:00:00+00:00
[2024-07-16T02:56:06.632+0000] {warnings.py:112} WARNING - /home/***/.local/lib/python3.12/site-packages/***/task/task_runner/standard_task_runner.py:61: DeprecationWarning: This process (pid=127) is multi-threaded, use of fork() may lead to deadlocks in the child.
  pid = os.fork()

[2024-07-16T02:56:06.634+0000] {standard_task_runner.py:63} INFO - Started process 129 to run task
[2024-07-16T02:56:06.634+0000] {standard_task_runner.py:90} INFO - Running: ['***', 'tasks', 'run', 'kubernetes_operator_example', 'kubernetes_task', 'scheduled__2024-07-15T00:00:00+00:00', '--job-id', '330', '--raw', '--subdir', 'DAGS_FOLDER/my_dag.py', '--cfg-path', '/tmp/tmpzdnnht6a']
[2024-07-16T02:56:06.637+0000] {standard_task_runner.py:91} INFO - Job 330: Subtask kubernetes_task
[2024-07-16T02:56:06.688+0000] {task_command.py:426} INFO - Running <TaskInstance: kubernetes_operator_example.kubernetes_task scheduled__2024-07-15T00:00:00+00:00 [running]> on host 3d1f449535f3
[2024-07-16T02:56:06.810+0000] {taskinstance.py:2648} INFO - Exporting env vars: AIRFLOW_CTX_DAG_OWNER='***' AIRFLOW_CTX_DAG_ID='kubernetes_operator_example' AIRFLOW_CTX_TASK_ID='kubernetes_task' AIRFLOW_CTX_EXECUTION_DATE='2024-07-15T00:00:00+00:00' AIRFLOW_CTX_TRY_NUMBER='2' AIRFLOW_CTX_DAG_RUN_ID='scheduled__2024-07-15T00:00:00+00:00'
[2024-07-16T02:56:06.812+0000] {taskinstance.py:430} INFO - ::endgroup::
[2024-07-16T02:56:06.820+0000] {pod.py:1121} INFO - Building pod kubernetes-task-lht8lh0o with labels: {'dag_id': 'kubernetes_operator_example', 'task_id': 'kubernetes_task', 'run_id': 'scheduled__2024-07-15T0000000000-9faa06fd6', 'kubernetes_pod_operator': 'True', 'try_number': '2'}
[2024-07-16T02:56:06.832+0000] {taskinstance.py:441} INFO - ::group::Post task execution logs
[2024-07-16T02:56:06.833+0000] {taskinstance.py:2905} ERROR - Task failed with exception
Traceback (most recent call last):
  File "/home/airflow/.local/lib/python3.12/site-packages/airflow/providers/cncf/kubernetes/hooks/kubernetes.py", line 267, in _get_default_client
    config.load_incluster_config(client_configuration=self.client_configuration)
  File "/home/airflow/.local/lib/python3.12/site-packages/kubernetes/config/incluster_config.py", line 121, in load_incluster_config
    try_refresh_token=try_refresh_token).load_and_set(client_configuration)
                                         ^^^^^^^^^^^^^^^^^^^^^^^^^^^^^^^^^^
  File "/home/airflow/.local/lib/python3.12/site-packages/kubernetes/config/incluster_config.py", line 54, in load_and_set
    self._load_config()
  File "/home/airflow/.local/lib/python3.12/site-packages/kubernetes/config/incluster_config.py", line 62, in _load_config
    raise ConfigException("Service host/port is not set.")
kubernetes.config.config_exception.ConfigException: Service host/port is not set.

During handling of the above exception, another exception occurred:

Traceback (most recent call last):
  File "/home/airflow/.local/lib/python3.12/site-packages/airflow/models/taskinstance.py", line 465, in _execute_task
    result = _execute_callable(context=context, **execute_callable_kwargs)
             ^^^^^^^^^^^^^^^^^^^^^^^^^^^^^^^^^^^^^^^^^^^^^^^^^^^^^^^^^^^^^
  File "/home/airflow/.local/lib/python3.12/site-packages/airflow/models/taskinstance.py", line 432, in _execute_callable
    return execute_callable(context=context, **execute_callable_kwargs)
           ^^^^^^^^^^^^^^^^^^^^^^^^^^^^^^^^^^^^^^^^^^^^^^^^^^^^^^^^^^^^
  File "/home/airflow/.local/lib/python3.12/site-packages/airflow/models/baseoperator.py", line 401, in wrapper
    return func(self, *args, **kwargs)
           ^^^^^^^^^^^^^^^^^^^^^^^^^^^
  File "/home/airflow/.local/lib/python3.12/site-packages/airflow/providers/cncf/kubernetes/operators/pod.py", line 591, in execute
    return self.execute_sync(context)
           ^^^^^^^^^^^^^^^^^^^^^^^^^^
  File "/home/airflow/.local/lib/python3.12/site-packages/airflow/providers/cncf/kubernetes/operators/pod.py", line 599, in execute_sync
    self.pod_request_obj = self.build_pod_request_obj(context)
                           ^^^^^^^^^^^^^^^^^^^^^^^^^^^^^^^^^^^
  File "/home/airflow/.local/lib/python3.12/site-packages/airflow/providers/cncf/kubernetes/operators/pod.py", line 1130, in build_pod_request_obj
    "airflow_kpo_in_cluster": str(self.hook.is_in_cluster),
                                  ^^^^^^^^^^^^^^^^^^^^^^^
  File "/home/airflow/.local/lib/python3.12/site-packages/airflow/providers/cncf/kubernetes/hooks/kubernetes.py", line 283, in is_in_cluster
    self.api_client  # so we can determine if we are in_cluster or not
    ^^^^^^^^^^^^^^^
  File "/usr/local/lib/python3.12/functools.py", line 995, in __get__
    val = self.func(instance)
          ^^^^^^^^^^^^^^^^^^^
  File "/home/airflow/.local/lib/python3.12/site-packages/airflow/providers/cncf/kubernetes/hooks/kubernetes.py", line 291, in api_client
    return self.get_conn()
           ^^^^^^^^^^^^^^^
  File "/home/airflow/.local/lib/python3.12/site-packages/airflow/providers/cncf/kubernetes/hooks/kubernetes.py", line 259, in get_conn
    return self._get_default_client(cluster_context=cluster_context)
           ^^^^^^^^^^^^^^^^^^^^^^^^^^^^^^^^^^^^^^^^^^^^^^^^^^^^^^^^^
  File "/home/airflow/.local/lib/python3.12/site-packages/airflow/providers/cncf/kubernetes/hooks/kubernetes.py", line 272, in _get_default_client
    config.load_kube_config(
  File "/home/airflow/.local/lib/python3.12/site-packages/kubernetes/config/kube_config.py", line 815, in load_kube_config
    loader = _get_kube_config_loader(
             ^^^^^^^^^^^^^^^^^^^^^^^^
  File "/home/airflow/.local/lib/python3.12/site-packages/kubernetes/config/kube_config.py", line 772, in _get_kube_config_loader
    raise ConfigException(
kubernetes.config.config_exception.ConfigException: Invalid kube-config file. No configuration found.
[2024-07-16T02:56:06.847+0000] {taskinstance.py:1206} INFO - Marking task as FAILED. dag_id=kubernetes_operator_example, task_id=kubernetes_task, run_id=scheduled__2024-07-15T00:00:00+00:00, execution_date=20240715T000000, start_date=20240716T025606, end_date=20240716T025606
[2024-07-16T02:56:06.862+0000] {standard_task_runner.py:110} ERROR - Failed to execute job 330 for task kubernetes_task (Invalid kube-config file. No configuration found.; 129)
[2024-07-16T02:56:06.888+0000] {local_task_job_runner.py:240} INFO - Task exited with return code 1
[2024-07-16T02:56:06.909+0000] {taskinstance.py:3503} INFO - 0 downstream tasks scheduled from follow-on schedule check
[2024-07-16T02:56:06.910+0000] {local_task_job_runner.py:222} INFO - ::endgroup::
